025-02-04 05:27:46,483 - __main__ - ERROR - Error running bot: Cannot close a running event loop
2025-02-04 05:27:46,483 - __main__ - ERROR - Error running application: Cannot close a running event loop
2025-02-04 05:27:46,483 - __main__ - INFO - Application shutdown complete
Traceback (most recent call last):
  File "/home/runner/workspace/.pythonlibs/lib/python3.11/site-packages/telegram/ext/_application.py", line 1076, in __run
    loop.run_until_complete(self.start())
  File "/home/runner/workspace/.pythonlibs/lib/python3.11/site-packages/nest_asyncio.py", line 98, in run_until_complete
    return f.result()
           ^^^^^^^^^^
  File "/nix/store/clx0mcir7qw8zk36zbr4jra789g3knf6-python3-3.11.10/lib/python3.11/asyncio/futures.py", line 203, in result
    raise self._exception.with_traceback(self._exception_tb)
  File "/nix/store/clx0mcir7qw8zk36zbr4jra789g3knf6-python3-3.11.10/lib/python3.11/asyncio/tasks.py", line 277, in __step
    result = coro.send(None)
             ^^^^^^^^^^^^^^^
  File "/home/runner/workspace/.pythonlibs/lib/python3.11/site-packages/telegram/ext/_application.py", line 610, in start
    raise RuntimeError("This Application is already running!")
RuntimeError: This Application is already running!

During handling of the above exception, another exception occurred:

Traceback (most recent call last):
  File "/home/runner/workspace/main.py", line 58, in <module>
    main()
  File "/home/runner/workspace/main.py", line 50, in main
    asyncio.run(run_bot())
  File "/home/runner/workspace/.pythonlibs/lib/python3.11/site-packages/nest_asyncio.py", line 30, in run
    return loop.run_until_complete(task)
           ^^^^^^^^^^^^^^^^^^^^^^^^^^^^^
  File "/home/runner/workspace/.pythonlibs/lib/python3.11/site-packages/nest_asyncio.py", line 98, in run_until_complete
    return f.result()
           ^^^^^^^^^^
  File "/nix/store/clx0mcir7qw8zk36zbr4jra789g3knf6-python3-3.11.10/lib/python3.11/asyncio/futures.py", line 203, in result
    raise self._exception.with_traceback(self._exception_tb)
  File "/nix/store/clx0mcir7qw8zk36zbr4jra789g3knf6-python3-3.11.10/lib/python3.11/asyncio/tasks.py", line 277, in __step
    result = coro.send(None)
             ^^^^^^^^^^^^^^^
  File "/home/runner/workspace/main.py", line 35, in run_bot
    await app.run_polling(drop_pending_updates=True)
          ^^^^^^^^^^^^^^^^^^^^^^^^^^^^^^^^^^^^^^^^^^
  File "/home/runner/workspace/.pythonlibs/lib/python3.11/site-packages/telegram/ext/_application.py", line 868, in run_polling
    return self.__run(
           ^^^^^^^^^^^
  File "/home/runner/workspace/.pythonlibs/lib/python3.11/site-packages/telegram/ext/_application.py", line 1099, in __run
    loop.close()
  File "/nix/store/clx0mcir7qw8zk36zbr4jra789g3knf6-python3-3.11.10/lib/python3.11/asyncio/unix_events.py", line 68, in close
    super().close()
  File "/nix/store/clx0mcir7qw8zk36zbr4jra789g3knf6-python3-3.11.10/lib/python3.11/asyncio/selector_events.py", line 88, in close
    raise RuntimeError("Cannot close a running event loop")
RuntimeError: Cannot close a running event loop
